Workbook
Name CIUDAD: [1]LISTAS!$L$2:$L$5
Name Lista_servicios: [2]LISTAS!$E$2:$E$353
Name Lista_unidad_negocio: [1]LISTAS!$J$2:$J$23

Sheet DASHBOARD
A1: ESTRUCTURA DEL COSTO POR PROGRAMA Y USO DE RECURSOS MÉDICOS
A2: Análisis por ruta clínica – Cifras promedio por paciente
B3: Programa: | C3: Cuidado Respiratorio | Q3: Ruta Normal (12m) | T3: Ruta Ecopetrol (18m)
A5: 1 RESUMEN EJECUTIVO – COSTO POR PROGRAMA | H5: ="2 ANATOMÍA DEL COSTO – "&$C$3 -> 2 ANATOMÍA DEL COSTO – Cuidado Respiratorio | O5: ="3 PARETO DE COSTOS – "&$C$3 -> 3 PARETO DE COSTOS – Cuidado Respiratorio
A23: ="Los 3 programas de mayor costo concentran "&TEXT(Calculos!I22,"0%")&" del total (Normal)." -> Los 3 programas de mayor costo concentran 43% del total (Normal). | H23: ="El "&TEXT(Calculos!I24,"0%")&" del costo de "&$C$3&" se concentra en "&Calculos!I23&"." -> El 41% del costo de Cuidado Respiratorio se concentra en Consultas. | O23: ="Las 2 categorías principales explican "&TEXT(Calculos!I25,"0%")&" del costo." -> Las 2 categorías principales explican 73% del costo.
A25: ="4 ESTRUCTURA DE SERVICIOS – "&$C$3 -> 4 ESTRUCTURA DE SERVICIOS – Cuidado Respiratorio | H25: 5 COMPARATIVO NORMAL (12m) VS ECOPETROL (18m) | O25: 6 MAPA ESTRATÉGICO DE IMPACTO ECONÓMICO
A26: Categoría | D26: Nº serv. | E26: Costo total | G26: % total | H26: Concepto | J26: Normal (12m) | L26: Ecopetrol (18m) | N26: Variación
A27: =Calculos!H8 -> Consultas | D27: =SUMIFS(BASE12MESES!$AC:$AC,BASE12MESES!$AG:$AG,Calculos!$I$4,BASE12MESES!$C:$C,Calculos!H8) -> 17 | E27: =Calculos!I8 -> 273505.04 | G27: =Calculos!K8 -> 0.40578445 | H27: =Calculos!H17 -> Costo total por paciente | J27: =Calculos!I17 -> 674015.57 | L27: =Calculos!J17 -> 1007999.4 | N27: =Calculos!K17 -> 0.49551352
A28: =Calculos!H9 -> Diagnosticos | D28: =SUMIFS(BASE12MESES!$AC:$AC,BASE12MESES!$AG:$AG,Calculos!$I$4,BASE12MESES!$C:$C,Calculos!H9) -> 2 | E28: =Calculos!I9 -> 21589.016 | G28: =Calculos!K9 -> 0.032030441 | H28: =Calculos!H18 -> Número total de servicios | J28: =Calculos!I18 -> 47 | L28: =Calculos!J18 -> 59 | N28: =Calculos!K18 -> 0.25531915
A29: =Calculos!H10 -> Terapias | D29: =SUMIFS(BASE12MESES!$AC:$AC,BASE12MESES!$AG:$AG,Calculos!$I$4,BASE12MESES!$C:$C,Calculos!H10) -> 2 | E29: =Calculos!I10 -> 4921.1722 | G29: =Calculos!K10 -> 0.0073012738 | H29: =Calculos!H19 -> Costo promedio mensual | J29: =Calculos!I19 -> 56167.964 | L29: =Calculos!J19 -> 55999.966 | N29: =Calculos!K19 -> -0.0029909869
A30: =Calculos!H11 -> Educacion | D30: =SUMIFS(BASE12MESES!$AC:$AC,BASE12MESES!$AG:$AG,Calculos!$I$4,BASE12MESES!$C:$C,Calculos!H11) -> 12 | E30: =Calculos!I11 -> 152921.06 | G30: =Calculos!K11 -> 0.2268806 | H30: =Calculos!H20 -> Costo promedio por servicio | J30: =Calculos!I20 -> 14340.757 | L30: =Calculos!J20 -> 17084.736 | N30: =Calculos!K20 -> 0.19134128
A31: =Calculos!H12 -> Gestion y seguimiento | D31: =SUMIFS(BASE12MESES!$AC:$AC,BASE12MESES!$AG:$AG,Calculos!$I$4,BASE12MESES!$C:$C,Calculos!H12) -> 14 | E31: =Calculos!I12 -> 221079.28 | G31: =Calculos!K12 -> 0.32800323
A32: TOTAL | D32: =SUM(D27:D31) -> 47 | E32: =SUM(Calculos!I8:I12) -> 674015.57 | G32: =SUM(G27:G31) -> 1 | H32: ="Ecopetrol varía el costo por paciente en "&TEXT(Calculos!K17,"+0%;-0%")&" frente a la ruta Normal (18 vs 12 meses)." -> Ecopetrol varía el costo por paciente en +50% frente a la ruta Normal (18 vs 12 meses).
A46: Estos análisis permiten identificar oportunidades de optimización, priorizar recursos y mejorar el valor en salud. | Fuente: Costos por Programa y Uso de Recursos Médicos

Sheet COSTOS SERVICIOS
A1: COSTO SERVICIOS 2025 | E1: EQUIVALENCIAS COSTO SERVICIOS 2026
A2: Servicio | B2: Valor | C2: Valor evento (SALUD TOTAl) | E2: Ciudad Servicio | F2: Sede | G2: Unidad de Negocio | H2: Columna1 | I2: Columna2 | J2: Columna3 | K2: CUPS | L2: SERVICIO | M2: VALOR
A3: ACTIVIDAD EDUCATIVA / PROGRAMAS | B3: 6486 | C3: - | E3: BUCARAMANGA_AREA_METR | F3: SEDE EL PRADO | G3: PROGRAMAS INTEGRALES | H3: 890201 | I3: CONSULTA PRIMERA VEZ MEDICINA GENERAL | J3: =_xlfn.CONCAT(E3,"-",F3,"-",G3,"-",I3) -> BUCARAMANGA_AREA_METR-SEDE EL PRADO-PROGRAMAS INTEGRALES-CONSULTA PRIMERA VEZ MEDICINA GENERAL | K3: CPI_78 | L3: CONSULTA PRIMERA VEZ MEDICINA GENERAL / PROGRAMAS | M3: =_xlfn.XLOOKUP(J3,[1]!Tabla1[CONCAT DETALLE],[1]!Tabla1[COSTO ACTUAL]) -> 24009.73
A4: CAMINATA 6 MINUTOS / PROGRAMAS | B4: 76840 | C4: 131250 | E4: BUCARAMANGA_AREA_METR | F4: SEDE EL PRADO | G4: PROGRAMAS INTEGRALES | H4: 890206 | I4: NUTRICION PRIMERA VEZ | J4: =_xlfn.CONCAT(E4,"-",F4,"-",G4,"-",I4) -> BUCARAMANGA_AREA_METR-SEDE EL PRADO-PROGRAMAS INTEGRALES-NUTRICION PRIMERA VEZ | K4: CPI_74 | L4: NUTRICION PRIMERA VEZ / PROGRAMAS | M4: =_xlfn.XLOOKUP(J4,[1]!Tabla1[CONCAT DETALLE],[1]!Tabla1[COSTO ACTUAL]) -> 20406.133
A5: CAPACIDAD DE DIFUSION / PROGRAMAS | B5: 74241 | C5: 68685 | E5: BUCARAMANGA_AREA_METR | F5: SEDE EL PRADO | G5: PROGRAMAS INTEGRALES | H5: 890208 | I5: PSICOLOGIA PRIMERA VEZ | J5: =_xlfn.CONCAT(E5,"-",F5,"-",G5,"-",I5) -> BUCARAMANGA_AREA_METR-SEDE EL PRADO-PROGRAMAS INTEGRALES-PSICOLOGIA PRIMERA VEZ | K5: CPI_76 | L5: PSICOLOGIA PRIMERA VEZ / PROGRAMAS | M5: =_xlfn.XLOOKUP(J5,[1]!Tabla1[CONCAT DETALLE],[1]!Tabla1[COSTO ACTUAL]) -> 18768.368
A6: CIERRE TERAPIA RESPIRATORIA/ PROGRAMAS | B6: 20860 | C6: 15000 | E6: BUCARAMANGA_AREA_METR | F6: SEDE EL PRADO | G6: PROGRAMAS INTEGRALES | H6: 890211 | I6: FISIOTERAPIA PRIMERA VEZ | J6: =_xlfn.CONCAT(E6,"-",F6,"-",G6,"-",I6) -> BUCARAMANGA_AREA_METR-SEDE EL PRADO-PROGRAMAS INTEGRALES-FISIOTERAPIA PRIMERA VEZ | K6: CPI_81 | L6: FISIOTERAPIA PRIMERA VEZ / PROGRAMAS | M6: =_xlfn.XLOOKUP(J6,[1]!Tabla1[CONCAT DETALLE],[1]!Tabla1[COSTO ACTUAL]) -> 19368.009
A7: CONSULTA CONTROL ALERGOLOGIA / PROGRAMAS | B7: 66667 | C7: 65000 | E7: BUCARAMANGA_AREA_METR | F7: SEDE EL PRADO | G7: PROGRAMAS INTEGRALES | H7: 890301 | I7: CONSULTA CONTROL MEDICINA GENERAL | J7: =_xlfn.CONCAT(E7,"-",F7,"-",G7,"-",I7) -> BUCARAMANGA_AREA_METR-SEDE EL PRADO-PROGRAMAS INTEGRALES-CONSULTA CONTROL MEDICINA GENERAL | K7: CPI_79 | L7: CONSULTA CONTROL MEDICINA GENERAL / PROGRAMAS | M7: =_xlfn.XLOOKUP(J7,[1]!Tabla1[CONCAT DETALLE],[1]!Tabla1[COSTO ACTUAL]) -> 24009.73
A8: CONSULTA CONTROL CARDIOLOGIA / PROGRAMAS | B8: 50000 | C8: 90000 | E8: BUCARAMANGA_AREA_METR | F8: SEDE EL PRADO | G8: PROGRAMAS INTEGRALES | H8: 890301 | I8: CONSULTA CONTROL MEDICINA GENERAL | J8: =_xlfn.CONCAT(E8,"-",F8,"-",G8,"-",I8) -> BUCARAMANGA_AREA_METR-SEDE EL PRADO-PROGRAMAS INTEGRALES-CONSULTA CONTROL MEDICINA GENERAL | K8: CPI_79 | L8: CONSULTA CONTROL MEDICINA GENERAL / PROGRAMAS | M8: =_xlfn.XLOOKUP(J8,[1]!Tabla1[CONCAT DETALLE],[1]!Tabla1[COSTO ACTUAL]) -> 24009.73
A9: CONSULTA CONTROL MEDICINA INTERNA / PROGRAMAS | B9: 35000 | C9: - | E9: BUCARAMANGA_AREA_METR | F9: SEDE EL PRADO | G9: PROGRAMAS INTEGRALES | H9: 890301 | I9: CONSULTA CONTROL MEDICINA GENERAL | J9: =_xlfn.CONCAT(E9,"-",F9,"-",G9,"-",I9) -> BUCARAMANGA_AREA_METR-SEDE EL PRADO-PROGRAMAS INTEGRALES-CONSULTA CONTROL MEDICINA GENERAL | K9: CPI_79 | L9: CONSULTA CONTROL MEDICINA GENERAL / PROGRAMAS (Todas las que requiera el paciente) | M9: =_xlfn.XLOOKUP(J9,[1]!Tabla1[CONCAT DETALLE],[1]!Tabla1[COSTO ACTUAL]) -> 24009.73
A10: CONSULTA CONTROL NEUMOLOGIA ADULTO / PROGRAMAS | B10: 50000 | C10: 50000 | E10: BUCARAMANGA_AREA_METR | F10: SEDE EL PRADO | G10: PROGRAMAS INTEGRALES | H10: 890305 | I10: ENFERMERIA PRIMERA VEZ | J10: =_xlfn.CONCAT(E10,"-",F10,"-",G10,"-",I10) -> BUCARAMANGA_AREA_METR-SEDE EL PRADO-PROGRAMAS INTEGRALES-ENFERMERIA PRIMERA VEZ | K10: 890305 | L10: ENFERMERIA PRIMERA VEZ/PROGRAMAS | M10: =_xlfn.XLOOKUP(J10,[1]!Tabla1[CONCAT DETALLE],[1]!Tabla1[COSTO ACTUAL]) -> 21014.397
A11: CONSULTA CONTROL NEUMOLOGIA PEDIATRICA / PROGRAMAS | B11: 64700 | C11: 90000 | E11: BUCARAMANGA_AREA_METR | F11: SEDE EL PRADO | G11: PROGRAMAS INTEGRALES | H11: 890305 | I11: ENFERMERIA CONTROL | J11: =_xlfn.CONCAT(E11,"-",F11,"-",G11,"-",I11) -> BUCARAMANGA_AREA_METR-SEDE EL PRADO-PROGRAMAS INTEGRALES-ENFERMERIA CONTROL | K11: CPI_80 | L11: ENFERMERIA CONTROL / PROGRAMAS | M11: =_xlfn.XLOOKUP(J11,[1]!Tabla1[CONCAT DETALLE],[1]!Tabla1[COSTO ACTUAL]) -> 21014.397
A12: CONSULTA ESPECIALIZADA CONTROL REHABILITACIoN/PROGRAMAS | B12: 64700 | C12: - | E12: BUCARAMANGA_AREA_METR | F12: SEDE EL PRADO | G12: PROGRAMAS INTEGRALES | H12: 890306 | I12: NUTRICION CONTROL | J12: =_xlfn.CONCAT(E12,"-",F12,"-",G12,"-",I12) -> BUCARAMANGA_AREA_METR-SEDE EL PRADO-PROGRAMAS INTEGRALES-NUTRICION CONTROL | K12: CPI_75 | L12: NUTRICION CONTROL / PROGRAMAS | M12: =_xlfn.XLOOKUP(J12,[1]!Tabla1[CONCAT DETALLE],[1]!Tabla1[COSTO ACTUAL]) -> 22052.521
A13: CONSULTA ESPECIALIZADA PRIMERA VEZ REHABILITACIoN/PROGRAMAS | B13: 64700 | C13: - | E13: BUCARAMANGA_AREA_METR | F13: SEDE EL PRADO | G13: PROGRAMAS INTEGRALES | H13: 890308 | I13: PSICOLOGIA CONTROL | J13: =_xlfn.CONCAT(E13,"-",F13,"-",G13,"-",I13) -> BUCARAMANGA_AREA_METR-SEDE EL PRADO-PROGRAMAS INTEGRALES-PSICOLOGIA CONTROL | K13: CPI_77 | L13: PSICOLOGIA CONTROL / PROGRAMAS | M13: =_xlfn.XLOOKUP(J13,[1]!Tabla1[CONCAT DETALLE],[1]!Tabla1[COSTO ACTUAL]) -> 20414.756
A14: CONSULTA PRIMERA VEZ ALERGOLOGIA / PROGRAMAS | B14: 66667 | C14: 65000 | E14: BUCARAMANGA_AREA_METR | F14: SEDE EL PRADO | G14: PROGRAMAS INTEGRALES | H14: CPI_01 | I14: INGRESO PROGRAMAS INTEGRALES | J14: =_xlfn.CONCAT(E14,"-",F14,"-",G14,"-",I14) -> BUCARAMANGA_AREA_METR-SEDE EL PRADO-PROGRAMAS INTEGRALES-INGRESO PROGRAMAS INTEGRALES | K14: CPI_01 | L14: INGRESO PROGRAMAS INTEGRALES | M14: =_xlfn.XLOOKUP(J14,[1]!Tabla1[CONCAT DETALLE],[1]!Tabla1[COSTO ACTUAL]) -> 20552.756
A15: CONSULTA PRIMERA VEZ CARDIOLOGIA / PROGRAMAS | B15: 50000 | C15: 90000 | E15: BUCARAMANGA_AREA_METR | F15: SEDE FOSUNAB | G15: SERVICIO MEDICO | H15: CPI_11 | I15: CONSULTA PRIMERA VEZ NEUMOLOGIA ADULTO | J15: =_xlfn.CONCAT(E15,"-",F15,"-",G15,"-",I15) -> BUCARAMANGA_AREA_METR-SEDE FOSUNAB-SERVICIO MEDICO-CONSULTA PRIMERA VEZ NEUMOLOGIA ADULTO | K15: CPI_11 | L15: CONSULTA PRIMERA VEZ NEUMOLOGIA ADULTO / PROGRAMAS | M15: =_xlfn.XLOOKUP(J15,[1]!Tabla1[CONCAT DETALLE],[1]!Tabla1[COSTO ACTUAL]) -> 67398.099
A16: CONSULTA PRIMERA VEZ MEDICINA INTERNA / PROGRAMAS | B16: 35000 | C16: - | E16: BUCARAMANGA_AREA_METR | F16: SEDE FOSUNAB | G16: SERVICIO MEDICO | H16: CPI_12 | I16: CONSULTA CONTROL NEUMOLOGIA ADULTO | J16: =_xlfn.CONCAT(E16,"-",F16,"-",G16,"-",I16) -> BUCARAMANGA_AREA_METR-SEDE FOSUNAB-SERVICIO MEDICO-CONSULTA CONTROL NEUMOLOGIA ADULTO | K16: CPI_12 | L16: CONSULTA CONTROL NEUMOLOGIA ADULTO / PROGRAMAS (Segun indicacion medica) | M16: =_xlfn.XLOOKUP(J16,[1]!Tabla1[CONCAT DETALLE],[1]!Tabla1[COSTO ACTUAL]) -> 67398.099
A17: CONSULTA PRIMERA VEZ NEUMOLOGIA ADULTO / PROGRAMAS | B17: 50000 | C17: 50000 | E17: BUCARAMANGA_AREA_METR | F17: SEDE FOSUNAB | G17: SERVICIO MEDICO | H17: CPI_13 | I17: CONSULTA PRIMERA VEZ NEUMOLOGIA PEDIATRICA | J17: =_xlfn.CONCAT(E17,"-",F17,"-",G17,"-",I17) -> BUCARAMANGA_AREA_METR-SEDE FOSUNAB-SERVICIO MEDICO-CONSULTA PRIMERA VEZ NEUMOLOGIA PEDIATRICA | K17: CPI_13 | L17: CONSULTA PRIMERA VEZ NEUMOLOGIA PEDIATRICA / PROGRAMAS | M17: =_xlfn.XLOOKUP(J17,[1]!Tabla1[CONCAT DETALLE],[1]!Tabla1[COSTO ACTUAL]) -> 83398.099
A18: CONSULTA PRIMERA VEZ NEUMOLOGIA PEDIATRICA / PROGRAMAS | B18: 64700 | C18: 90000 | E18: BUCARAMANGA_AREA_METR | F18: SEDE FOSUNAB | G18: SERVICIO MEDICO | H18: CPI_14 | I18: CONSULTA CONTROL NEUMOLOGIA PEDIATRICA | J18: =_xlfn.CONCAT(E18,"-",F18,"-",G18,"-",I18) -> BUCARAMANGA_AREA_METR-SEDE FOSUNAB-SERVICIO MEDICO-CONSULTA CONTROL NEUMOLOGIA PEDIATRICA | K18: CPI_14 | L18: CONSULTA CONTROL NEUMOLOGIA PEDIATRICA / PROGRAMAS (Segun indicacion medica) | M18: =_xlfn.XLOOKUP(J18,[1]!Tabla1[CONCAT DETALLE],[1]!Tabla1[COSTO ACTUAL]) -> 77398.099
A19: CONSULTA PRIORITARIA/ PROGRAMAS | B19: 50000 | C19: - | E19: BUCARAMANGA_AREA_METR | F19: SEDE FOSUNAB | G19: LABORATORIO PULMONAR | H19: 893805 | I19: ESPIROMETRIA PRE Y POST BRONCODILATADORES | J19: =_xlfn.CONCAT(E19,"-",F19,"-",G19,"-",I19) -> BUCARAMANGA_AREA_METR-SEDE FOSUNAB-LABORATORIO PULMONAR-ESPIROMETRIA PRE Y POST BRONCODILATADORES | K19: CPI_15 | L19: ESPIROMETRIA PRE Y POST BRONCODILATADORES / PROGRAMAS | M19: =_xlfn.XLOOKUP(J19,[1]!Tabla1[CONCAT DETALLE],[1]!Tabla1[COSTO ACTUAL]) -> 43480.817
A20: CONTACTO DE SEGUIMIENTO Y/O TELEFONICO / PROGRAMAS | B20: 3215 | C20: - | E20: BUCARAMANGA_AREA_METR | F20: SEDE FOSUNAB | G20: LABORATORIO PULMONAR | H20: 893805 | I20: ESPIROMETRIA PRE Y POST BRONCODILATADORES | J20: =_xlfn.CONCAT(E20,"-",F20,"-",G20,"-",I20) -> BUCARAMANGA_AREA_METR-SEDE FOSUNAB-LABORATORIO PULMONAR-ESPIROMETRIA PRE Y POST BRONCODILATADORES | K20: CPI_15 | L20: ESPIROMETRIA PRE Y POST BRONCODILATADORES / PROGRAMAS (Segun condicion de salud) | M20: =_xlfn.XLOOKUP(J20,[1]!Tabla1[CONCAT DETALLE],[1]!Tabla1[COSTO ACTUAL]) -> 43480.817
A21: CONTROL CESACIoN TABAQUICA/ PROGRAMAS | B21: 9241 | C21: - | E21: BUCARAMANGA_AREA_METR | F21: SEDE EL PRADO | G21: PROGRAMAS INTEGRALES | H21: CPI_02 | I21: REHABILITACION INGRESO | J21: =_xlfn.CONCAT(E21,"-",F21,"-",G21,"-",I21) -> BUCARAMANGA_AREA_METR-SEDE EL PRADO-PROGRAMAS INTEGRALES-REHABILITACION INGRESO | K21: CPI_02 | L21: REHABILITACION INGRESO / PROGRAMAS | M21: =_xlfn.XLOOKUP(J21,[1]!Tabla1[CONCAT DETALLE],[1]!Tabla1[COSTO ACTUAL]) -> 31881.452
A22: CONTROL TERAPIA RESPIRATORIA/ PROGRAMAS | B22: 20860 | C22: 15000 | E22: BUCARAMANGA_AREA_METR | F22: SEDE EL PRADO | G22: PROGRAMAS INTEGRALES | H22: CPI_02 | I22: REHABILITACION CONTROL | J22: =_xlfn.CONCAT(E22,"-",F22,"-",G22,"-",I22) -> BUCARAMANGA_AREA_METR-SEDE EL PRADO-PROGRAMAS INTEGRALES-REHABILITACION CONTROL | K22: CPI_03 | L22: REHABILITACION CONTROL / PROGRAMAS (1, 2 o 3 Sesiones semana) | M22: 8780.1199
A23: EGRESO CESACIoN TABAQUICA | B23: 5130 | C23: - | E23: BUCARAMANGA_AREA_METR | F23: SEDE FOSUNAB | G23: CLINICA DE ALERGIAS | I23: CONSULTA CONTROL ALERGOLOGIA | J23: =_xlfn.CONCAT(E23,"-",F23,"-",G23,"-",I23) -> BUCARAMANGA_AREA_METR-SEDE FOSUNAB-CLINICA DE ALERGIAS-CONSULTA CONTROL ALERGOLOGIA | K23: CPI_18 | L23: CONSULTA CONTROL ALERGOLOGIA / PROGRAMAS (Segun indicacion medica) | M23: =_xlfn.XLOOKUP(J23,[1]!Tabla1[CONCAT DETALLE],[1]!Tabla1[COSTO ACTUAL]) -> 85060.599
A24: EGRESO PROGRAMAS INTEGRALES | B24: 6429 | C24: - | E24: BUCARAMANGA_AREA_METR | F24: SEDE FOSUNAB | G24: CLINICA DE ALERGIAS | I24: CONSULTA PRIMERA VEZ ALERGOLOGIA | J24: =_xlfn.CONCAT(E24,"-",F24,"-",G24,"-",I24) -> BUCARAMANGA_AREA_METR-SEDE FOSUNAB-CLINICA DE ALERGIAS-CONSULTA PRIMERA VEZ ALERGOLOGIA | K24: CPI_19 | L24: CONSULTA PRIMERA VEZ ALERGOLOGIA / PROGRAMAS | M24: =_xlfn.XLOOKUP(J24,[1]!Tabla1[CONCAT DETALLE],[1]!Tabla1[COSTO ACTUAL]) -> 85060.599
A25: ENFERMERIA CONTROL / PROGRAMAS | B25: 10166 | C25: - | E25: BUCARAMANGA_AREA_METR | F25: SEDE FOSUNAB | G25: CLINICA DE ALERGIAS | I25: Prick Test | J25: =_xlfn.CONCAT(E25,"-",F25,"-",G25,"-",I25) -> BUCARAMANGA_AREA_METR-SEDE FOSUNAB-CLINICA DE ALERGIAS-Prick Test | K25: CPI_20 | L25: Prick Test / PROGRAMAS | M25: =_xlfn.XLOOKUP(J25,[1]!Tabla1[CONCAT DETALLE],[1]!Tabla1[COSTO ACTUAL]) -> 76461.627
A26: ESPIROMETRIA PRE Y POST BRONCODILATADORES / PROGRAMAS | B26: 49381 | C26: 41996 | E26: BUCARAMANGA_AREA_METR | F26: SEDE FOSUNAB | G26: LABORATORIO PULMONAR | H26: CPI_21 | I26: FRACCIóN EXHALADA DE óxido NíTRICO (FeNo) | J26: =_xlfn.CONCAT(E26,"-",F26,"-",G26,"-",I26) -> BUCARAMANGA_AREA_METR-SEDE FOSUNAB-LABORATORIO PULMONAR-FRACCIóN EXHALADA DE óxido NíTRICO (FeNo) | K26: CPI_21 | L26: FRACCIóN EXHALADA DE óxido NíTRICO (FeNo) / PROGRAMAS | M26: =_xlfn.XLOOKUP(J26,[1]!Tabla1[CONCAT DETALLE],[1]!Tabla1[COSTO ACTUAL]) -> 37683.908
A27: FISIOTERAPIA CONTROL / PROGRAMAS | B27: 25943 | C27: - | E27: BUCARAMANGA_AREA_METR | F27: SEDE FOSUNAB | G27: LABORATORIO PULMONAR | H27: CPI_22 | I27: VOLUMENES PULMONARES POR PLETISMOGRAFIA PRE Y POST BRONCODILATADORES | J27: =_xlfn.CONCAT(E27,"-",F27,"-",G27,"-",I27) -> BUCARAMANGA_AREA_METR-SEDE FOSUNAB-LABORATORIO PULMONAR-VOLUMENES PULMONARES POR PLETISMOGRAFIA PRE Y POST BRONCODILATADORES | K27: CPI_22 | L27: VOLUMENES PULMONARES POR PLETISMOGRAFIA PRE Y POST BRONCODILATADORES / PROGRAMAS | M27: =_xlfn.XLOOKUP(J27,[1]!Tabla1[CONCAT DETALLE],[1]!Tabla1[COSTO ACTUAL]) -> 65169.207
A28: FISIOTERAPIA PRIMERA VEZ / PROGRAMAS | B28: 25943 | C28: - | E28: BUCARAMANGA_AREA_METR | F28: SEDE FOSUNAB | G28: LABORATORIO PULMONAR | H28: 893815 | I28: PRUEBA DE BRONCOPROVOCACIÓN ESPECÍFICA (ALERGENO) O INESPECÍFICA | J28: =_xlfn.CONCAT(E28,"-",F28,"-",G28,"-",I28) -> BUCARAMANGA_AREA_METR-SEDE FOSUNAB-LABORATORIO PULMONAR-PRUEBA DE BRONCOPROVOCACIÓN ESPECÍFICA (ALERGENO) O INESPECÍFICA | K28: CPI_23 | L28: TEST DE METACOLINA / PROGRAMAS | M28: =_xlfn.XLOOKUP(J28,[1]!Tabla1[CONCAT DETALLE],[1]!Tabla1[COSTO ACTUAL]) -> 232601.87
A29: FRACCIóN EXHALADA DE óxido NíTRICO (FeNo) / PROGRAMAS | B29: 199445 | C29: 180000 | E29: BUCARAMANGA_AREA_METR | F29: SEDE FOSUNAB | G29: LABORATORIO PULMONAR | H29: CPI_24 | I29: OSCILOMETRIA DE IMPULSO | J29: =_xlfn.CONCAT(E29,"-",F29,"-",G29,"-",I29) -> BUCARAMANGA_AREA_METR-SEDE FOSUNAB-LABORATORIO PULMONAR-OSCILOMETRIA DE IMPULSO | K29: CPI_24 | L29: OSCILOMETRIA DE IMPULSO / PROGRAMAS (Pacientes que no logran realizar espirometria) | M29: =_xlfn.XLOOKUP(J29,[1]!Tabla1[CONCAT DETALLE],[1]!Tabla1[COSTO ACTUAL]) -> 67391.282
A30: INGRESO CESACIoN TABAQUICA | B30: 9241 | C30: - | E30: BUCARAMANGA_AREA_METR | F30: SEDE FOSUNAB | G30: LABORATORIO PULMONAR | H30: CPI_26 | I30: CAPACIDAD DE DIFUSION CON MONOXIDO DE CARBONO | J30: =_xlfn.CONCAT(E30,"-",F30,"-",G30,"-",I30) -> BUCARAMANGA_AREA_METR-SEDE FOSUNAB-LABORATORIO PULMONAR-CAPACIDAD DE DIFUSION CON MONOXIDO DE CARBONO | K30: CPI_26 | L30: CAPACIDAD DE DIFUSION / PROGRAMAS | M30: =_xlfn.XLOOKUP(J30,[1]!Tabla1[CONCAT DETALLE],[1]!Tabla1[COSTO ACTUAL]) -> 68748.387
A31: INGRESO PROGRAMAS INTEGRALES | B31: 6429 | C31: - | E31: BUCARAMANGA_AREA_METR | F31: SEDE EL PRADO | G31: PROGRAMAS INTEGRALES | H31: CPI_04 | I31: CONSULTA PRIMERA VEZ MEDICINA INTERNA | J31: =_xlfn.CONCAT(E31,"-",F31,"-",G31,"-",I31) -> BUCARAMANGA_AREA_METR-SEDE EL PRADO-PROGRAMAS INTEGRALES-CONSULTA PRIMERA VEZ MEDICINA INTERNA | K31: CPI_04 | L31: CONSULTA PRIMERA VEZ MEDICINA INTERNA / PROGRAMAS | M31: =_xlfn.XLOOKUP(J31,[1]!Tabla1[CONCAT DETALLE],[1]!Tabla1[COSTO ACTUAL]) -> 55794.182
A32: NUTRICION CONTROL / PROGRAMAS | B32: 10608 | C32: - | E32: BUCARAMANGA_AREA_METR | F32: SEDE EL PRADO | G32: PROGRAMAS INTEGRALES | H32: CPI_04 | I32: CONSULTA PRIMERA VEZ MEDICINA INTERNA | J32: =_xlfn.CONCAT(E32,"-",F32,"-",G32,"-",I32) -> BUCARAMANGA_AREA_METR-SEDE EL PRADO-PROGRAMAS INTEGRALES-CONSULTA PRIMERA VEZ MEDICINA INTERNA | K32: CPI_04 | L32: CONSULTA PRIMERA VEZ MEDICINA INTERNA / PROGRAMAS | M32: =_xlfn.XLOOKUP(J32,[1]!Tabla1[CONCAT DETALLE],[1]!Tabla1[COSTO ACTUAL]) -> 55794.182
A33: NUTRICION PRIMERA VEZ / PROGRAMAS | B33: 10608 | C33: - | E33: BUCARAMANGA_AREA_METR | F33: SEDE EL PRADO | G33: PROGRAMAS INTEGRALES | H33: CPI_05 | I33: CONSULTA CONTROL MEDICINA INTERNA | J33: =_xlfn.CONCAT(E33,"-",F33,"-",G33,"-",I33) -> BUCARAMANGA_AREA_METR-SEDE EL PRADO-PROGRAMAS INTEGRALES-CONSULTA CONTROL MEDICINA INTERNA | K33: CPI_05 | L33: CONSULTA CONTROL MEDICINA INTERNA / PROGRAMAS (Segun indicacion medica) | M33: =_xlfn.XLOOKUP(J33,[1]!Tabla1[CONCAT DETALLE],[1]!Tabla1[COSTO ACTUAL]) -> 55794.182
A34: OSCILOMETRIA DE IMPULSO / PROGRAMAS | B34: 146900 | C34: 265200 | E34: BUCARAMANGA_AREA_METR | F34: SEDE EL PRADO | G34: PROGRAMAS INTEGRALES | H34: CPI_08 | I34: EGRESO PROGRAMAS INTEGRALES | J34: =_xlfn.CONCAT(E34,"-",F34,"-",G34,"-",I34) -> BUCARAMANGA_AREA_METR-SEDE EL PRADO-PROGRAMAS INTEGRALES-EGRESO PROGRAMAS INTEGRALES | K34: CPI_08 | L34: EGRESO PROGRAMAS INTEGRALES | M34: =_xlfn.XLOOKUP(J34,[1]!Tabla1[CONCAT DETALLE],[1]!Tabla1[COSTO ACTUAL]) -> 12908.292
A35: PARTICIPACIoN JUNTA MEDICA/ PROGRAMAS | B35: 60000 | C35: 320000 | E35: BUCARAMANGA_AREA_METR | F35: SEDE EL PRADO | G35: PROGRAMAS INTEGRALES | H35: CPI_09 | I35: ACTIVIDAD EDUCATIVA | J35: =_xlfn.CONCAT(E35,"-",F35,"-",G35,"-",I35) -> BUCARAMANGA_AREA_METR-SEDE EL PRADO-PROGRAMAS INTEGRALES-ACTIVIDAD EDUCATIVA | K35: CPI_09 | L35: ACTIVIDAD EDUCATIVA / PROGRAMAS | M35: =_xlfn.XLOOKUP(J35,[1]!Tabla1[CONCAT DETALLE],[1]!Tabla1[COSTO ACTUAL]) -> 12743.422
A36: Prick Test / PROGRAMAS | B36: 130685 | C36: 195000 | E36: BUCARAMANGA_AREA_METR | F36: SEDE CABECERA | G36: TERAPIA RESPIRATORIA | H36: CPI_32 | I36: PRIMERA VEZ TERAPIA RESPIRATORIA2 | J36: =_xlfn.CONCAT(E36,"-",F36,"-",G36,"-",I36) -> BUCARAMANGA_AREA_METR-SEDE CABECERA-TERAPIA RESPIRATORIA-PRIMERA VEZ TERAPIA RESPIRATORIA2 | K36: CPI_32 | L36: PRIMERA VEZ TERAPIA RESPIRATORIA/ PROGRAMAS (Segun indicacion medica) | M36: =_xlfn.XLOOKUP(J36,[1]!Tabla1[CONCAT DETALLE],[1]!Tabla1[COSTO ACTUAL]) -> 31714.221
A37: PRIMERA VEZ TERAPIA RESPIRATORIA/ PROGRAMAS | B37: 20860 | C37: 15000 | E37: BUCARAMANGA_AREA_METR | F37: SEDE CABECERA | G37: TERAPIA RESPIRATORIA | H37: CPI_34 | I37: CIERRE TERAPIA RESPIRATORIA2 | J37: =_xlfn.CONCAT(E37,"-",F37,"-",G37,"-",I37) -> BUCARAMANGA_AREA_METR-SEDE CABECERA-TERAPIA RESPIRATORIA-CIERRE TERAPIA RESPIRATORIA2 | K37: CPI_33 | L37: CONTROL TERAPIA RESPIRATORIA/ PROGRAMAS (Segun indicacion medica) | M37: =_xlfn.XLOOKUP(J37,[1]!Tabla1[CONCAT DETALLE],[1]!Tabla1[COSTO ACTUAL]) -> 31714.221
A38: TRABAJO SOCIAL PRIMERA VEZ/PROGRAMAS | B38: 10166 | C38: - | E38: BUCARAMANGA_AREA_METR | F38: SEDE EL PRADO | G38: PROGRAMAS INTEGRALES | H38: CPI_09 | I38: ACTIVIDAD EDUCATIVA | J38: =_xlfn.CONCAT(E38,"-",F38,"-",G38,"-",I38) -> BUCARAMANGA_AREA_METR-SEDE EL PRADO-PROGRAMAS INTEGRALES-ACTIVIDAD EDUCATIVA | K38: CPI_09 | L38: ACTIVIDAD EDUCATIVA / PROGRAMAS (Grupo de apoyo semanal) | M38: =_xlfn.XLOOKUP(J38,[1]!Tabla1[CONCAT DETALLE],[1]!Tabla1[COSTO ACTUAL]) -> 12743.422
A39: TRABAJO SOCIAL CONTROL/PROGRAMAS | B39: 10166 | C39: - | E39: BUCARAMANGA_AREA_METR | F39: SEDE EL PRADO | G39: PROGRAMAS INTEGRALES | H39: CPI_10 | I39: CONTACTO DE SEGUIMIENTO Y/O TELEFONICO | J39: =_xlfn.CONCAT(E39,"-",F39,"-",G39,"-",I39) -> BUCARAMANGA_AREA_METR-SEDE EL PRADO-PROGRAMAS INTEGRALES-CONTACTO DE SEGUIMIENTO Y/O TELEFONICO | K39: CPI_10 | L39: CONTACTO DE SEGUIMIENTO Y/O TELEFONICO / PROGRAMAS | M39: =_xlfn.XLOOKUP(J39,[1]!Tabla1[CONCAT DETALLE],[1]!Tabla1[COSTO ACTUAL]) -> 15634.853
A40: INTERVENCIoN DOMICILIARIA TRABAJO SOCIAL/PROGRAMAS | B40: 10166 | C40: - | E40: BUCARAMANGA_AREA_METR | F40: SEDE FOSUNAB | G40: PROGRAMAS INTEGRALES | H40: CPI_16 | I40: CONSULTA PRIMERA VEZ CARDIOLOGIA | J40: =_xlfn.CONCAT(E40,"-",F40,"-",G40,"-",I40) -> BUCARAMANGA_AREA_METR-SEDE FOSUNAB-PROGRAMAS INTEGRALES-CONSULTA PRIMERA VEZ CARDIOLOGIA | K40: CPI_16 | L40: CONSULTA PRIMERA VEZ CARDIOLOGIA / PROGRAMAS | M40: =_xlfn.XLOOKUP(J40,[1]!Tabla1[CONCAT DETALLE],[1]!Tabla1[COSTO ACTUAL]) -> 58766.154
...

Sheet BASE12MESES
A1: Servicios del Programa: | B1: Programa Rehabilitacion Pulmonar / Asma | C1: CATEGORIA | D1: MES 1 | E1: COSTO | F1: MES 2 | G1: COSTO2 | H1: MES 3 | I1: COSTO3 | J1: MES 4 | K1: COSTO4 | L1: MES 5 | M1: COSTO5 | N1: MES 6 | O1: COSTO6 | P1: MES 7 | Q1: COSTO7 | R1: MES 8 | S1: COSTO8 | T1: MES 9 | U1: COSTO9 | V1: MES 10 | W1: COSTO10 | X1: MES 11 | Y1: COSTO11 | Z1: MES 12 | AA1: COSTO12 | AB1: TOTAL | AC1: TOTAL SERVICIOS | AD1: Modalidad | AE1: % de las personas que lo usaron | AF1: VALOR COSTO | AG1: RUTA | AH1: DURACION
A2: CPI_01 | B2: INGRESO PROGRAMAS INTEGRALES | C2: Gestion y seguimiento | D2: 1 | E2: 20552.756 | G2: 0 | I2: 0 | K2: 0 | M2: 0 | O2: 0 | Q2: 0 | S2: 0 | U2: 0 | W2: 0 | Y2: 0 | AA2: 0 | AB2: 20552.756 | AC2: 1 | AD2: FIJO | AE2: 1 | AF2: 20552.756 | AG2: ASMA | AH2: 12
A3: CPI_83 | B3: TRABAJO SOCIAL PRIMERA VEZ/PROGRAMAS | C3: Consultas | D3: 1 | E3: 17887.389 | G3: 0 | I3: 0 | K3: 0 | M3: 0 | O3: 0 | Q3: 0 | S3: 0 | U3: 0 | W3: 0 | Y3: 0 | AA3: 0 | AB3: 17887.389 | AC3: 1 | AD3: FIJO | AE3: 1 | AF3: 17887.389 | AG3: ASMA | AH3: 12
A4: CPI_84 | B4: TRABAJO SOCIAL CONTROL/PROGRAMAS | C4: Consultas | E4: 0 | G4: 0 | I4: 0 | K4: 0 | M4: 0 | O4: 0 | Q4: 0 | S4: 0 | U4: 0 | W4: 0 | Y4: 0 | Z4: 1 | AA4: 17887.389 | AB4: 17887.389 | AC4: 1 | AD4: FIJO | AE4: 1 | AF4: 17887.389 | AG4: ASMA | AH4: 12
A5: CPI_85 | B5: INTERVENCIoN DOMICILIARIA TRABAJO SOCIAL/PROGRAMAS (Segun indicacion medica) | C5: Gestion y seguimiento | E5: 0 | G5: 0 | H5: 1 | I5: 17887.389 | K5: 0 | M5: 0 | O5: 0 | Q5: 0 | S5: 0 | U5: 0 | W5: 0 | Y5: 0 | AA5: 0 | AB5: 17887.389 | AC5: 1 | AD5: FIJO | AE5: 1 | AF5: 17887.389 | AG5: ASMA | AH5: 12
A6: CPI_10 | B6: CONTACTO DE SEGUIMIENTO Y/O TELEFONICO / PROGRAMAS | C6: Gestion y seguimiento | D6: 1 | E6: 15634.853 | F6: 1 | G6: 15634.853 | H6: 1 | I6: 15634.853 | K6: 0 | M6: 0 | N6: 1 | O6: 15634.853 | Q6: 0 | S6: 0 | T6: 1 | U6: 15634.853 | W6: 0 | Y6: 0 | Z6: 1 | AA6: 15634.853 | AB6: 93809.118 | AC6: 6 | AD6: FIJO | AE6: 1 | AF6: 93809.118 | AG6: ASMA | AH6: 12
A7: CPI_09 | B7: ACTIVIDAD EDUCATIVA / PROGRAMAS | C7: Educacion | D7: 1 | E7: 12743.422 | F7: 1 | G7: 12743.422 | H7: 1 | I7: 12743.422 | J7: 1 | K7: 12743.422 | L7: 1 | M7: 12743.422 | N7: 1 | O7: 12743.422 | P7: 1 | Q7: 12743.422 | R7: 1 | S7: 12743.422 | T7: 1 | U7: 12743.422 | V7: 1 | W7: 12743.422 | X7: 1 | Y7: 12743.422 | Z7: 1 | AA7: 12743.422 | AB7: 152921.06 | AC7: 12 | AD7: FIJO | AE7: 1 | AF7: 152921.06 | AG7: ASMA | AH7: 12
A8: CPI_74 | B8: NUTRICION PRIMERA VEZ / PROGRAMAS | C8: Consultas | D8: 1 | E8: 20406.133 | G8: 0 | I8: 0 | K8: 0 | M8: 0 | O8: 0 | Q8: 0 | S8: 0 | U8: 0 | W8: 0 | Y8: 0 | AA8: 0 | AB8: 20406.133 | AC8: 1 | AD8: FIJO | AE8: 1 | AF8: 20406.133 | AG8: ASMA | AH8: 12
A9: CPI_76 | B9: PSICOLOGIA PRIMERA VEZ / PROGRAMAS | C9: Consultas | D9: 1 | E9: 18768.368 | G9: 0 | I9: 0 | K9: 0 | M9: 0 | O9: 0 | Q9: 0 | S9: 0 | U9: 0 | W9: 0 | Y9: 0 | AA9: 0 | AB9: 18768.368 | AC9: 1 | AD9: FIJO | AE9: 1 | AF9: 18768.368 | AG9: ASMA | AH9: 12
A10: CPI_81 | B10: FISIOTERAPIA PRIMERA VEZ / PROGRAMAS | C10: Consultas | E10: 0 | G10: 0 | H10: 1 | I10: 19368.009 | K10: 0 | M10: 0 | O10: 0 | Q10: 0 | S10: 0 | U10: 0 | W10: 0 | Y10: 0 | AA10: 0 | AB10: 19368.009 | AC10: 1 | AD10: FIJO | AE10: 1 | AF10: 19368.009 | AG10: ASMA | AH10: 12
A11: CPI_03 | B11: REHABILITACION CONTROL / PROGRAMAS (1, 2 o 3 Sesiones semana) | C11: Terapias | E11: 0 | G11: 0 | H11: 8 | I11: 70240.959 | J11: 8 | K11: 70240.959 | L11: 8 | M11: 70240.959 | N11: 8 | O11: 70240.959 | P11: 8 | Q11: 70240.959 | R11: 8 | S11: 70240.959 | T11: 8 | U11: 70240.959 | V11: 8 | W11: 70240.959 | X11: 8 | Y11: 70240.959 | Z11: 8 | AA11: 70240.959 | AB11: 702409.59 | AC11: 80 | AD11: FIJO | AE11: 1 | AF11: 702409.59 | AG11: ASMA | AH11: 12
A12: CPI_75 | B12: NUTRICION CONTROL / PROGRAMAS | C12: Consultas | E12: 0 | G12: 0 | I12: 0 | K12: 0 | M12: 0 | O12: 0 | Q12: 0 | S12: 0 | U12: 0 | W12: 0 | Y12: 0 | Z12: 1 | AA12: 22052.521 | AB12: 22052.521 | AC12: 1 | AD12: FIJO | AE12: 1 | AF12: 22052.521 | AG12: ASMA | AH12: 12
A13: CPI_77 | B13: PSICOLOGIA CONTROL / PROGRAMAS | C13: Consultas | E13: 0 | G13: 0 | I13: 0 | K13: 0 | M13: 0 | O13: 0 | Q13: 0 | S13: 0 | U13: 0 | W13: 0 | Y13: 0 | Z13: 1 | AA13: 20414.756 | AB13: 20414.756 | AC13: 1 | AD13: FIJO | AE13: 1 | AF13: 20414.756 | AG13: ASMA | AH13: 12
A14: CPI_15 | B14: ESPIROMETRIA PRE Y POST BRONCODILATADORES / PROGRAMAS | C14: Diagnosticos | D14: 1 | E14: 43480.817 | G14: 0 | I14: 0 | K14: 0 | M14: 0 | O14: 0 | Q14: 0 | S14: 0 | U14: 0 | W14: 0 | Y14: 0 | Z14: 1 | AA14: 43480.817 | AB14: 86961.634 | AC14: 2 | AD14: FIJO | AE14: 1 | AF14: 86961.634 | AG14: ASMA | AH14: 12
A15: CPI_28 | B15: CAMINATA 6 MINUTOS / PROGRAMAS | C15: Diagnosticos | E15: 0 | G15: 0 | H15: 1 | I15: 19392.627 | K15: 0 | M15: 0 | O15: 0 | Q15: 0 | S15: 0 | U15: 0 | W15: 0 | Y15: 0 | Z15: 1 | AA15: 19392.627 | AB15: 38785.254 | AC15: 2 | AD15: FIJO | AE15: 1 | AF15: 38785.254 | AG15: ASMA | AH15: 12
A16: CPI_21 | B16: FRACCIóN EXHALADA DE óxido NíTRICO (FeNo) / PROGRAMAS | C16: Diagnosticos | D16: 1 | E16: 37683.908 | G16: 0 | I16: 0 | K16: 0 | M16: 0 | O16: 0 | Q16: 0 | S16: 0 | U16: 0 | W16: 0 | Y16: 0 | AA16: 0 | AB16: 37683.908 | AC16: 1 | AD16: PROBABILISTICO | AE16: 0.13116124 | AF16: 4942.668 | AG16: ASMA | AH16: 12
A17: CPI_22 | B17: VOLUMENES PULMONARES POR PLETISMOGRAFIA PRE Y POST BRONCODILATADORES / PROGRAMAS | C17: Diagnosticos | D17: 1 | E17: 65169.207 | G17: 0 | I17: 0 | K17: 0 | M17: 0 | O17: 0 | Q17: 0 | S17: 0 | U17: 0 | W17: 0 | Y17: 0 | AA17: 0 | AB17: 65169.207 | AC17: 1 | AD17: PROBABILISTICO | AE17: 0.020885547 | AF17: 1361.0946 | AG17: ASMA | AH17: 12
A18: CPI_26 | B18: CAPACIDAD DE DIFUSION / PROGRAMAS | C18: Diagnosticos | D18: 1 | E18: 68748.387 | G18: 0 | I18: 0 | K18: 0 | M18: 0 | O18: 0 | Q18: 0 | S18: 0 | U18: 0 | W18: 0 | Y18: 0 | AA18: 0 | AB18: 68748.387 | AC18: 1 | AD18: PROBABILISTICO | AE18: 0.015037594 | AF18: 1033.8103 | AG18: ASMA | AH18: 12
A19: CPI_18 | B19: CONSULTA CONTROL ALERGOLOGIA / PROGRAMAS (Segun indicacion medica) | C19: Consultas | D19: 1 | E19: 85060.599 | G19: 0 | I19: 0 | K19: 0 | M19: 0 | O19: 0 | Q19: 0 | S19: 0 | U19: 0 | W19: 0 | Y19: 0 | AA19: 0 | AB19: 85060.599 | AC19: 1 | AD19: PROBABILISTICO | AE19: 0.29741019 | AF19: 25297.889 | AG19: ASMA | AH19: 12
A20: CPI_20 | B20: Prick Test / PROGRAMAS | C20: Diagnosticos | D20: 1 | E20: 76461.627 | G20: 0 | I20: 0 | K20: 0 | M20: 0 | O20: 0 | Q20: 0 | S20: 0 | U20: 0 | W20: 0 | Y20: 0 | AA20: 0 | AB20: 76461.627 | AC20: 1 | AD20: FIJO | AE20: 1 | AF20: 76461.627 | AG20: ASMA | AH20: 12
A21: CPI_13 | B21: CONSULTA PRIMERA VEZ NEUMOLOGIA PEDIATRICA / PROGRAMAS | C21: Consultas | D21: 1 | E21: 83398.099 | G21: 0 | I21: 0 | K21: 0 | M21: 0 | O21: 0 | Q21: 0 | S21: 0 | U21: 0 | W21: 0 | Y21: 0 | AA21: 0 | AB21: 83398.099 | AC21: 1 | AD21: PROBABILISTICO | AE21: 0.021720969 | AF21: 1811.4875 | AG21: ASMA | AH21: 12
A22: CPI_14 | B22: CONSULTA CONTROL NEUMOLOGIA PEDIATRICA / PROGRAMAS (Segun indicacion medica) | C22: Consultas | E22: 0 | G22: 0 | I22: 0 | K22: 0 | M22: 0 | O22: 0 | Q22: 0 | S22: 0 | U22: 0 | W22: 0 | Y22: 0 | Z22: 1 | AA22: 77398.099 | AB22: 77398.099 | AC22: 1 | AD22: PROBABILISTICO | AE22: 0.71345029 | AF22: 55219.696 | AG22: ASMA | AH22: 12
A23: CPI_12 | B23: CONSULTA CONTROL NEUMOLOGIA ADULTO / PROGRAMAS (Segun indicacion medica) | C23: Consultas | E23: 0 | G23: 0 | I23: 0 | K23: 0 | M23: 0 | N23: 1 | O23: 67398.099 | Q23: 0 | S23: 0 | U23: 0 | W23: 0 | Y23: 0 | Z23: 1 | AA23: 67398.099 | AB23: 134796.2 | AC23: 2 | AD23: FIJO | AE23: 1 | AF23: 134796.2 | AG23: ASMA | AH23: 12
A24: CPI_11 | B24: CONSULTA PRIMERA VEZ NEUMOLOGIA ADULTO / PROGRAMAS | C24: Consultas | D24: 1 | E24: 67398.099 | G24: 0 | I24: 0 | K24: 0 | M24: 0 | O24: 0 | Q24: 0 | S24: 0 | U24: 0 | W24: 0 | Y24: 0 | AA24: 0 | AB24: 67398.099 | AC24: 1 | AD24: FIJO | AE24: 1 | AF24: 67398.099 | AG24: ASMA | AH24: 12
A25: CPI_80 | B25: ENFERMERIA CONTROL / PROGRAMAS | C25: Consultas | E25: 0 | G25: 0 | I25: 0 | K25: 0 | M25: 0 | O25: 0 | Q25: 0 | S25: 0 | U25: 0 | W25: 0 | Y25: 0 | Z25: 1 | AA25: 21014.397 | AB25: 21014.397 | AC25: 1 | AD25: FIJO | AE25: 0.72598162 | AF25: 15256.066 | AG25: ASMA | AH25: 12
A26: CPI_33 | B26: CONTROL TERAPIA RESPIRATORIA/ PROGRAMAS (Segun indicacion medica) | C26: Terapias | D26: 1 | E26: 31714.221 | G26: 0 | I26: 0 | K26: 0 | M26: 0 | O26: 0 | Q26: 0 | S26: 0 | U26: 0 | W26: 0 | Y26: 0 | AA26: 0 | AB26: 31714.221 | AC26: 1 | AD26: PROBABILISTICO | AE26: 0.1144528 | AF26: 3629.7813 | AG26: ASMA | AH26: 12
A27: CPI_32 | B27: PRIMERA VEZ TERAPIA RESPIRATORIA/ PROGRAMAS (Segun indicacion medica) | C27: Terapias | D27: 1 | E27: 31714.221 | G27: 0 | I27: 0 | K27: 0 | M27: 0 | O27: 0 | Q27: 0 | S27: 0 | U27: 0 | W27: 0 | Y27: 0 | AA27: 0 | AB27: 31714.221 | AC27: 1 | AD27: PROBABILISTICO | AE27: 0.055973266 | AF27: 1775.1485 | AG27: ASMA | AH27: 12
A28: CPI_24 | B28: OSCILOMETRIA DE IMPULSO / PROGRAMAS (Pacientes que no logran realizar espirometria) | C28: Diagnosticos | D28: 1 | E28: 67391.282 | G28: 0 | I28: 0 | K28: 0 | M28: 0 | O28: 0 | Q28: 0 | S28: 0 | U28: 0 | W28: 0 | Y28: 0 | AA28: 0 | AB28: 67391.282 | AC28: 1 | AD28: PROBABILISTICO | AE28: 0.055973266 | AF28: 3772.1102 | AG28: ASMA | AH28: 12
A29: CPI_30 | B29: PARTICIPACIoN JUNTA MEDICA/ PROGRAMAS (Segun indicacion medica) | C29: Gestion y seguimiento | E29: 0 | G29: 0 | I29: 0 | K29: 0 | M29: 0 | N29: 1 | O29: 145259.19 | Q29: 0 | S29: 0 | U29: 0 | W29: 0 | Y29: 0 | AA29: 0 | AB29: 145259.19 | AC29: 1 | AD29: PROBABILISTICO | AE29: 0.035087719 | AF29: 5096.8138 | AG29: ASMA | AH29: 12
A30: CPI_06 | B30: CONSULTA PRIORITARIA/ PROGRAMAS (Todas las que requiera el paciente) | C30: Consultas | E30: 0 | G30: 0 | I30: 0 | K30: 0 | M30: 0 | O30: 0 | P30: 1 | Q30: 56420.693 | S30: 0 | U30: 0 | W30: 0 | Y30: 0 | AA30: 0 | AB30: 56420.693 | AC30: 1 | AD30: PROBABILISTICO | AE30: 0.46031746 | AF30: 25971.43 | AG30: ASMA | AH30: 12
A31: CPI_78 | B31: CONSULTA PRIMERA VEZ MEDICINA GENERAL / PROGRAMAS | C31: Consultas | D31: 1 | E31: 24009.73 | G31: 0 | I31: 0 | K31: 0 | M31: 0 | O31: 0 | Q31: 0 | S31: 0 | U31: 0 | W31: 0 | Y31: 0 | AA31: 0 | AB31: 24009.73 | AC31: 1 | AD31: PROBABILISTICO | AE31: 0.0025062657 | AF31: 60.174763 | AG31: ASMA | AH31: 12
A32: CPI_86 | B32: DEPORTOLOGIA PRIMERA VEZ/PROGRAMAS (solo si se requiere) | C32: Consultas | D32: 1 | E32: 60236.093 | G32: 0 | I32: 0 | K32: 0 | M32: 0 | O32: 0 | Q32: 0 | S32: 0 | U32: 0 | W32: 0 | Y32: 0 | AA32: 0 | AB32: 60236.093 | AC32: 1 | AD32: PROBABILISTICO | AE32: 0.025062657 | AF32: 1509.6765 | AG32: ASMA | AH32: 12
A33: CPI_87 | B33: DEPORTOLOGIA CONTROL/PROGRAMAS (solo si se requiere) | C33: Consultas | E33: 0 | G33: 0 | I33: 0 | K33: 0 | M33: 0 | O33: 0 | P33: 1 | Q33: 62748.232 | S33: 0 | U33: 0 | W33: 0 | Y33: 0 | AA33: 0 | AB33: 62748.232 | AC33: 1 | AD33: PROBABILISTICO | AE33: 0.0083542189 | AF33: 524.21247 | AG33: ASMA | AH33: 12
A34: CPI_88 | B34: DEPORTOLOGIA EGRESO/PROGRAMAS (solo si se requiere) | C34: Consultas | E34: 0 | G34: 0 | I34: 0 | K34: 0 | M34: 0 | O34: 0 | Q34: 0 | S34: 0 | U34: 0 | W34: 0 | Y34: 0 | Z34: 1 | AA34: 62748.232 | AB34: 62748.232 | AC34: 1 | AD34: PROBABILISTICO | AE34: 0 | AF34: 0 | AG34: ASMA | AH34: 12
A35: CPI_31 | B35: REHABILITACIoN EGRESO / PROGRAMAS | C35: Terapias | E35: 0 | G35: 0 | I35: 0 | K35: 0 | M35: 0 | O35: 0 | Q35: 0 | S35: 0 | U35: 0 | W35: 0 | Y35: 0 | Z35: 1 | AA35: 31881.452 | AB35: 31881.452 | AC35: 1 | AD35: FIJO | AE35: 1 | AF35: 31881.452 | AG35: ASMA | AH35: 12
A36: CPI_02 | B36: REHABILITACION INGRESO / PROGRAMAS | C36: Terapias | E36: 0 | G36: 0 | H36: 1 | I36: 31881.452 | K36: 0 | M36: 0 | O36: 0 | Q36: 0 | S36: 0 | U36: 0 | W36: 0 | Y36: 0 | AA36: 0 | AB36: 31881.452 | AC36: 1 | AD36: FIJO | AE36: 1 | AF36: 31881.452 | AG36: ASMA | AH36: 12
A37: CPI_79 | B37: CONSULTA CONTROL MEDICINA GENERAL / PROGRAMAS (Todas las que requiera el paciente) | C37: Consultas | E37: 0 | G37: 0 | I37: 0 | K37: 0 | M37: 0 | O37: 0 | Q37: 0 | S37: 0 | U37: 0 | W37: 0 | Y37: 0 | AA37: 0 | AB37: 0 | AC37: 0 | AD37: PROBABILISTICO | AE37: 0 | AF37: 0 | AG37: ASMA | AH37: 12
A38: CPI_23 | B38: PRUEBA DE BRONCOPROVOCACIÓN ESPECÍFICA (ALERGENO) O INESPECÍFICA | C38: Diagnosticos | D38: 1 | E38: 232601.87 | G38: 0 | I38: 0 | K38: 0 | M38: 0 | O38: 0 | Q38: 0 | S38: 0 | U38: 0 | W38: 0 | Y38: 0 | AA38: 0 | AB38: 232601.87 | AC38: 1 | AD38: PROBABILISTICO | AE38: 0.015037594 | AF38: 3497.7725 | AG38: ASMA | AH38: 12
A39: CPI_19 | B39: CONSULTA PRIMERA VEZ ALERGOLOGIA / PROGRAMAS | C39: Consultas | D39: 1 | E39: 85060.599 | G39: 0 | I39: 0 | K39: 0 | M39: 0 | O39: 0 | Q39: 0 | S39: 0 | U39: 0 | W39: 0 | Y39: 0 | AA39: 0 | AB39: 85060.599 | AC39: 1 | AD39: FIJO | AE39: 1 | AF39: 85060.599 | AG39: ASMA | AH39: 12
A40: CPI_72 | B40: CONSULTA ESPECIALIZADA PRIMERA VEZ REHABILITACIoN/PROGRAMAS | C40: Consultas | D40: 1 | E40: 26897.08 | G40: 0 | I40: 0 | K40: 0 | M40: 0 | O40: 0 | Q40: 0 | S40: 0 | U40: 0 | W40: 0 | Y40: 0 | AA40: 0 | AB40: 26897.08 | AC40: 1 | AD40: PROBABILISTICO | AE40: 0 | AF40: 0 | AG40: ASMA | AH40: 12
...

Sheet BASE18MESES
A1: Servicios del Programa: | B1: Programa Rehabilitacion Pulmonar / Asma | C1: CATEGORIA | D1: MES 1 | E1: COSTOS | F1: MES 2 | G1: COSTOS2 | H1: MES 3 | I1: COSTOS3 | J1: MES 4 | K1: COSTOS4 | L1: MES 5 | M1: COSTOS5 | N1: MES 6 | O1: COSTOS6 | P1: MES 7 | Q1: COSTOS7 | R1: MES 8 | S1: COSTOS8 | T1: MES 9 | U1: COSTOS9 | V1: MES 10 | W1: COSTOS10 | X1: MES 11 | Y1: COSTOS11 | Z1: MES 12 | AA1: COSTOS12 | AB1: MES 13 | AC1: COSTOS13 | AD1: MES 14 | AE1: COSTOS14 | AF1: MES 15 | AG1: COSTOS15 | AH1: MES 16 | AI1: COSTOS16 | AJ1: MES 17 | AK1: COSTOS17 | AL1: MES 18 | AM1: COSTOS18 | AN1: TOTAL | AO1: TOTAL SERVICIOS | AP1: Modalidad | AQ1: % de las personas que lo usaron | AR1: VALOR COSTO | AS1: RUTA | AT1: DURACION
A2: CPI_01 | B2: INGRESO PROGRAMAS INTEGRALES | C2: Gestion y seguimiento | D2: 1 | E2: 20552.756 | G2: 0 | I2: 0 | K2: 0 | M2: 0 | O2: 0 | Q2: 0 | S2: 0 | U2: 0 | W2: 0 | Y2: 0 | AA2: 0 | AC2: 0 | AE2: 0 | AG2: 0 | AI2: 0 | AK2: 0 | AM2: 0 | AN2: 20552.756 | AO2: 1 | AP2: FIJO | AQ2: 1 | AR2: 20552.756 | AS2: ASMA | AT2: 18
A3: CPI_83 | B3: TRABAJO SOCIAL PRIMERA VEZ/PROGRAMAS | C3: Consultas | D3: 1 | E3: 17887.389 | G3: 0 | I3: 0 | K3: 0 | M3: 0 | O3: 0 | Q3: 0 | S3: 0 | U3: 0 | W3: 0 | Y3: 0 | AA3: 0 | AC3: 0 | AE3: 0 | AG3: 0 | AI3: 0 | AK3: 0 | AM3: 0 | AN3: 17887.389 | AO3: 1 | AP3: FIJO | AQ3: 1 | AR3: 17887.389 | AS3: ASMA | AT3: 18
A4: CPI_84 | B4: TRABAJO SOCIAL CONTROL/PROGRAMAS | C4: Consultas | E4: 0 | G4: 0 | I4: 0 | K4: 0 | M4: 0 | O4: 0 | Q4: 0 | S4: 0 | U4: 0 | W4: 0 | Y4: 0 | AA4: 0 | AC4: 0 | AE4: 0 | AG4: 0 | AI4: 0 | AK4: 0 | AL4: 1 | AM4: 17887.389 | AN4: 17887.389 | AO4: 1 | AP4: FIJO | AQ4: 1 | AR4: 17887.389 | AS4: ASMA | AT4: 18
A5: CPI_85 | B5: INTERVENCIoN DOMICILIARIA TRABAJO SOCIAL/PROGRAMAS (Segun indicacion medica) | C5: Gestion y seguimiento | E5: 0 | G5: 0 | H5: 1 | I5: 17887.389 | K5: 0 | M5: 0 | O5: 0 | Q5: 0 | S5: 0 | U5: 0 | W5: 0 | Y5: 0 | AA5: 0 | AC5: 0 | AE5: 0 | AG5: 0 | AI5: 0 | AK5: 0 | AM5: 0 | AN5: 17887.389 | AO5: 1 | AP5: FIJO | AQ5: 1 | AR5: 17887.389 | AS5: ASMA | AT5: 18
A6: CPI_10 | B6: CONTACTO DE SEGUIMIENTO Y/O TELEFONICO / PROGRAMAS | C6: Gestion y seguimiento | D6: 1 | E6: 15634.853 | F6: 1 | G6: 15634.853 | H6: 1 | I6: 15634.853 | K6: 0 | M6: 0 | N6: 1 | O6: 15634.853 | Q6: 0 | S6: 0 | T6: 1 | U6: 15634.853 | W6: 0 | Y6: 0 | Z6: 1 | AA6: 15634.853 | AC6: 0 | AE6: 0 | AG6: 0 | AI6: 0 | AK6: 0 | AL6: 1 | AM6: 15634.853 | AN6: 109443.97 | AO6: 7 | AP6: FIJO | AQ6: 1 | AR6: 109443.97 | AS6: ASMA | AT6: 18
A7: CPI_09 | B7: ACTIVIDAD EDUCATIVA / PROGRAMAS | C7: Educacion | D7: 1 | E7: 10832.306 | F7: 1 | G7: 10832.306 | H7: 1 | I7: 10832.306 | J7: 1 | K7: 10832.306 | L7: 1 | M7: 10832.306 | N7: 1 | O7: 10832.306 | P7: 1 | Q7: 10832.306 | R7: 1 | S7: 10832.306 | T7: 1 | U7: 10832.306 | V7: 1 | W7: 10832.306 | X7: 1 | Y7: 10832.306 | Z7: 1 | AA7: 10832.306 | AB7: 1 | AC7: 10832.306 | AD7: 1 | AE7: 10832.306 | AF7: 1 | AG7: 10832.306 | AH7: 1 | AI7: 10832.306 | AJ7: 1 | AK7: 10832.306 | AL7: 1 | AM7: 10832.306 | AN7: 194981.5 | AO7: 18 | AP7: FIJO | AQ7: 1 | AR7: 194981.5 | AS7: ASMA | AT7: 18
A8: CPI_74 | B8: NUTRICION PRIMERA VEZ / PROGRAMAS | C8: Consultas | D8: 1 | E8: 20406.133 | G8: 0 | I8: 0 | K8: 0 | M8: 0 | O8: 0 | Q8: 0 | S8: 0 | U8: 0 | W8: 0 | Y8: 0 | AA8: 0 | AC8: 0 | AE8: 0 | AG8: 0 | AI8: 0 | AK8: 0 | AM8: 0 | AN8: 20406.133 | AO8: 1 | AP8: FIJO | AQ8: 1 | AR8: 20406.133 | AS8: ASMA | AT8: 18
A9: CPI_76 | B9: PSICOLOGIA PRIMERA VEZ / PROGRAMAS | C9: Consultas | D9: 1 | E9: 18768.368 | G9: 0 | I9: 0 | K9: 0 | M9: 0 | O9: 0 | Q9: 0 | S9: 0 | U9: 0 | W9: 0 | Y9: 0 | AA9: 0 | AC9: 0 | AE9: 0 | AG9: 0 | AI9: 0 | AK9: 0 | AM9: 0 | AN9: 18768.368 | AO9: 1 | AP9: FIJO | AQ9: 1 | AR9: 18768.368 | AS9: ASMA | AT9: 18
A10: CPI_81 | B10: FISIOTERAPIA PRIMERA VEZ / PROGRAMAS | C10: Consultas | E10: 0 | G10: 0 | H10: 1 | I10: 21404.19 | K10: 0 | M10: 0 | O10: 0 | Q10: 0 | S10: 0 | U10: 0 | W10: 0 | Y10: 0 | AA10: 0 | AC10: 0 | AE10: 0 | AG10: 0 | AI10: 0 | AK10: 0 | AM10: 0 | AN10: 21404.19 | AO10: 1 | AP10: FIJO | AQ10: 1 | AR10: 21404.19 | AS10: ASMA | AT10: 18
A11: CPI_03 | B11: REHABILITACION CONTROL / PROGRAMAS (1, 2 o 3 Sesiones semana) | C11: Terapias | E11: 0 | G11: 0 | H11: 8 | I11: 70240.959 | J11: 8 | K11: 70240.959 | L11: 8 | M11: 70240.959 | N11: 8 | O11: 70240.959 | P11: 8 | Q11: 70240.959 | R11: 8 | S11: 70240.959 | T11: 8 | U11: 70240.959 | V11: 8 | W11: 70240.959 | X11: 8 | Y11: 70240.959 | Z11: 8 | AA11: 70240.959 | AB11: 8 | AC11: 70240.959 | AD11: 8 | AE11: 70240.959 | AF11: 8 | AG11: 70240.959 | AH11: 8 | AI11: 70240.959 | AJ11: 8 | AK11: 70240.959 | AL11: 8 | AM11: 70240.959 | AN11: 1123855.3 | AO11: 128 | AP11: FIJO | AQ11: 1 | AR11: 1123855.3 | AS11: ASMA | AT11: 18
A12: CPI_75 | B12: NUTRICION CONTROL / PROGRAMAS | C12: Consultas | E12: 0 | G12: 0 | I12: 0 | K12: 0 | M12: 0 | O12: 0 | Q12: 0 | S12: 0 | U12: 0 | W12: 0 | Y12: 0 | AA12: 0 | AC12: 0 | AE12: 0 | AG12: 0 | AI12: 0 | AK12: 0 | AL12: 1 | AM12: 22052.521 | AN12: 22052.521 | AO12: 1 | AP12: FIJO | AQ12: 1 | AR12: 22052.521 | AS12: ASMA | AT12: 18
A13: CPI_77 | B13: PSICOLOGIA CONTROL / PROGRAMAS | C13: Consultas | E13: 0 | G13: 0 | I13: 0 | K13: 0 | M13: 0 | O13: 0 | Q13: 0 | S13: 0 | U13: 0 | W13: 0 | Y13: 0 | AA13: 0 | AC13: 0 | AE13: 0 | AG13: 0 | AI13: 0 | AK13: 0 | AL13: 1 | AM13: 20414.756 | AN13: 20414.756 | AO13: 1 | AP13: FIJO | AQ13: 1 | AR13: 20414.756 | AS13: ASMA | AT13: 18
A14: CPI_15 | B14: ESPIROMETRIA PRE Y POST BRONCODILATADORES / PROGRAMAS | C14: Diagnosticos | D14: 1 | E14: 43480.817 | G14: 0 | I14: 0 | K14: 0 | M14: 0 | O14: 0 | Q14: 0 | S14: 0 | U14: 0 | W14: 0 | Y14: 0 | AA14: 0 | AC14: 0 | AE14: 0 | AG14: 0 | AI14: 0 | AK14: 0 | AL14: 1 | AM14: 43480.817 | AN14: 86961.634 | AO14: 2 | AP14: FIJO | AQ14: 1 | AR14: 86961.634 | AS14: ASMA | AT14: 18
A15: CPI_28 | B15: CAMINATA 6 MINUTOS / PROGRAMAS | C15: Diagnosticos | E15: 0 | G15: 0 | H15: 1 | I15: 32117.317 | K15: 0 | M15: 0 | O15: 0 | Q15: 0 | S15: 0 | U15: 0 | W15: 0 | Y15: 0 | AA15: 0 | AC15: 0 | AE15: 0 | AG15: 0 | AI15: 0 | AK15: 0 | AL15: 1 | AM15: 32117.317 | AN15: 64234.635 | AO15: 2 | AP15: FIJO | AQ15: 1 | AR15: 64234.635 | AS15: ASMA | AT15: 18
A16: CPI_21 | B16: FRACCIóN EXHALADA DE óxido NíTRICO (FeNo) / PROGRAMAS | C16: Diagnosticos | D16: 1 | E16: 37683.908 | G16: 0 | I16: 0 | K16: 0 | M16: 0 | O16: 0 | Q16: 0 | S16: 0 | U16: 0 | W16: 0 | Y16: 0 | AA16: 0 | AC16: 0 | AE16: 0 | AG16: 0 | AI16: 0 | AK16: 0 | AM16: 0 | AN16: 37683.908 | AO16: 1 | AP16: PROBABILISTICO | AQ16: 0.13116124 | AR16: 4942.668 | AS16: ASMA | AT16: 18
A17: CPI_22 | B17: VOLUMENES PULMONARES POR PLETISMOGRAFIA PRE Y POST BRONCODILATADORES / PROGRAMAS | C17: Diagnosticos | D17: 1 | E17: 65169.207 | G17: 0 | I17: 0 | K17: 0 | M17: 0 | O17: 0 | Q17: 0 | S17: 0 | U17: 0 | W17: 0 | Y17: 0 | AA17: 0 | AC17: 0 | AE17: 0 | AG17: 0 | AI17: 0 | AK17: 0 | AM17: 0 | AN17: 65169.207 | AO17: 1 | AP17: PROBABILISTICO | AQ17: 0.020885547 | AR17: 1361.0946 | AS17: ASMA | AT17: 18
A18: CPI_26 | B18: CAPACIDAD DE DIFUSION / PROGRAMAS | C18: Diagnosticos | D18: 1 | E18: 68748.387 | G18: 0 | I18: 0 | K18: 0 | M18: 0 | O18: 0 | Q18: 0 | S18: 0 | U18: 0 | W18: 0 | Y18: 0 | AA18: 0 | AC18: 0 | AE18: 0 | AG18: 0 | AI18: 0 | AK18: 0 | AM18: 0 | AN18: 68748.387 | AO18: 1 | AP18: PROBABILISTICO | AQ18: 0.015037594 | AR18: 1033.8103 | AS18: ASMA | AT18: 18
A19: CPI_18 | B19: CONSULTA CONTROL ALERGOLOGIA / PROGRAMAS (Segun indicacion medica) | C19: Consultas | D19: 1 | E19: 85060.599 | G19: 0 | I19: 0 | K19: 0 | M19: 0 | O19: 0 | Q19: 0 | S19: 0 | U19: 0 | W19: 0 | Y19: 0 | AA19: 0 | AC19: 0 | AE19: 0 | AG19: 0 | AI19: 0 | AK19: 0 | AM19: 0 | AN19: 85060.599 | AO19: 1 | AP19: PROBABILISTICO | AQ19: 0.29741019 | AR19: 25297.889 | AS19: ASMA | AT19: 18
A20: CPI_20 | B20: Prick Test / PROGRAMAS | C20: Diagnosticos | D20: 1 | E20: 76461.627 | G20: 0 | I20: 0 | K20: 0 | M20: 0 | O20: 0 | Q20: 0 | S20: 0 | U20: 0 | W20: 0 | Y20: 0 | AA20: 0 | AC20: 0 | AE20: 0 | AG20: 0 | AI20: 0 | AK20: 0 | AM20: 0 | AN20: 76461.627 | AO20: 1 | AP20: FIJO | AQ20: 1 | AR20: 76461.627 | AS20: ASMA | AT20: 18
A21: CPI_13 | B21: CONSULTA PRIMERA VEZ NEUMOLOGIA PEDIATRICA / PROGRAMAS | C21: Consultas | D21: 1 | E21: 83398.099 | G21: 0 | I21: 0 | K21: 0 | M21: 0 | O21: 0 | Q21: 0 | S21: 0 | U21: 0 | W21: 0 | Y21: 0 | AA21: 0 | AC21: 0 | AE21: 0 | AG21: 0 | AI21: 0 | AK21: 0 | AM21: 0 | AN21: 83398.099 | AO21: 1 | AP21: PROBABILISTICO | AQ21: 0.021720969 | AR21: 1811.4875 | AS21: ASMA | AT21: 18
A22: CPI_14 | B22: CONSULTA CONTROL NEUMOLOGIA PEDIATRICA / PROGRAMAS (Segun indicacion medica) | C22: Consultas | E22: 0 | G22: 0 | I22: 0 | K22: 0 | M22: 0 | O22: 0 | Q22: 0 | S22: 0 | U22: 0 | W22: 0 | Y22: 0 | AA22: 0 | AC22: 0 | AE22: 0 | AG22: 0 | AI22: 0 | AK22: 0 | AL22: 1 | AM22: 77398.099 | AN22: 77398.099 | AO22: 1 | AP22: PROBABILISTICO | AQ22: 0.71345029 | AR22: 55219.696 | AS22: ASMA | AT22: 18
A23: CPI_12 | B23: CONSULTA CONTROL NEUMOLOGIA ADULTO / PROGRAMAS (Segun indicacion medica) | C23: Consultas | E23: 0 | G23: 0 | I23: 0 | K23: 0 | M23: 0 | N23: 1 | O23: 67398.099 | Q23: 0 | S23: 0 | U23: 0 | W23: 0 | Y23: 0 | Z23: 1 | AA23: 67398.099 | AC23: 0 | AE23: 0 | AG23: 0 | AI23: 0 | AK23: 0 | AL23: 1 | AM23: 67398.099 | AN23: 202194.3 | AO23: 3 | AP23: FIJO | AQ23: 1 | AR23: 202194.3 | AS23: ASMA | AT23: 18
A24: CPI_11 | B24: CONSULTA PRIMERA VEZ NEUMOLOGIA ADULTO / PROGRAMAS | C24: Consultas | D24: 1 | E24: 67398.099 | G24: 0 | I24: 0 | K24: 0 | M24: 0 | O24: 0 | Q24: 0 | S24: 0 | U24: 0 | W24: 0 | Y24: 0 | AA24: 0 | AC24: 0 | AE24: 0 | AG24: 0 | AI24: 0 | AK24: 0 | AM24: 0 | AN24: 67398.099 | AO24: 1 | AP24: FIJO | AQ24: 1 | AR24: 67398.099 | AS24: ASMA | AT24: 18
A25: CPI_80 | B25: ENFERMERIA CONTROL / PROGRAMAS | C25: Consultas | E25: 0 | G25: 0 | I25: 0 | K25: 0 | M25: 0 | O25: 0 | Q25: 0 | S25: 0 | U25: 0 | W25: 0 | Y25: 0 | AA25: 0 | AC25: 0 | AE25: 0 | AG25: 0 | AI25: 0 | AK25: 0 | AL25: 1 | AM25: 21014.397 | AN25: 21014.397 | AO25: 1 | AP25: FIJO | AQ25: 0.72598162 | AR25: 15256.066 | AS25: ASMA | AT25: 18
A26: CPI_33 | B26: CONTROL TERAPIA RESPIRATORIA/ PROGRAMAS (Segun indicacion medica) | C26: Terapias | D26: 1 | E26: 31714.221 | G26: 0 | I26: 0 | K26: 0 | M26: 0 | O26: 0 | Q26: 0 | S26: 0 | U26: 0 | W26: 0 | Y26: 0 | AA26: 0 | AC26: 0 | AE26: 0 | AG26: 0 | AI26: 0 | AK26: 0 | AM26: 0 | AN26: 31714.221 | AO26: 1 | AP26: PROBABILISTICO | AQ26: 0.1144528 | AR26: 3629.7813 | AS26: ASMA | AT26: 18
A27: CPI_32 | B27: PRIMERA VEZ TERAPIA RESPIRATORIA/ PROGRAMAS (Segun indicacion medica) | C27: Terapias | D27: 1 | E27: 31714.221 | G27: 0 | I27: 0 | K27: 0 | M27: 0 | O27: 0 | Q27: 0 | S27: 0 | U27: 0 | W27: 0 | Y27: 0 | AA27: 0 | AC27: 0 | AE27: 0 | AG27: 0 | AI27: 0 | AK27: 0 | AM27: 0 | AN27: 31714.221 | AO27: 1 | AP27: PROBABILISTICO | AQ27: 0.055973266 | AR27: 1775.1485 | AS27: ASMA | AT27: 18
A28: CPI_24 | B28: OSCILOMETRIA DE IMPULSO / PROGRAMAS (Pacientes que no logran realizar espirometria) | C28: Diagnosticos | D28: 1 | E28: 67391.282 | G28: 0 | I28: 0 | K28: 0 | M28: 0 | O28: 0 | Q28: 0 | S28: 0 | U28: 0 | W28: 0 | Y28: 0 | AA28: 0 | AC28: 0 | AE28: 0 | AG28: 0 | AI28: 0 | AK28: 0 | AM28: 0 | AN28: 67391.282 | AO28: 1 | AP28: PROBABILISTICO | AQ28: 0.055973266 | AR28: 3772.1102 | AS28: ASMA | AT28: 18
A29: CPI_30 | B29: PARTICIPACIoN JUNTA MEDICA/ PROGRAMAS (Segun indicacion medica) | C29: Gestion y seguimiento | E29: 0 | G29: 0 | I29: 0 | K29: 0 | M29: 0 | N29: 1 | O29: 145259.19 | Q29: 0 | S29: 0 | U29: 0 | W29: 0 | Y29: 0 | AA29: 0 | AC29: 0 | AE29: 0 | AG29: 0 | AI29: 0 | AK29: 0 | AM29: 0 | AN29: 145259.19 | AO29: 1 | AP29: PROBABILISTICO | AQ29: 0.035087719 | AR29: 5096.8138 | AS29: ASMA | AT29: 18
A30: CPI_06 | B30: CONSULTA PRIORITARIA/ PROGRAMAS (Todas las que requiera el paciente) | C30: Consultas | E30: 0 | G30: 0 | I30: 0 | K30: 0 | M30: 0 | O30: 0 | P30: 1 | Q30: 56420.693 | S30: 0 | U30: 0 | W30: 0 | Y30: 0 | AA30: 0 | AC30: 0 | AE30: 0 | AG30: 0 | AI30: 0 | AK30: 0 | AM30: 0 | AN30: 56420.693 | AO30: 1 | AP30: PROBABILISTICO | AQ30: 0.46031746 | AR30: 25971.43 | AS30: ASMA | AT30: 18
A31: CPI_78 | B31: CONSULTA PRIMERA VEZ MEDICINA GENERAL / PROGRAMAS | C31: Consultas | D31: 1 | E31: 18146.718 | G31: 0 | I31: 0 | K31: 0 | M31: 0 | O31: 0 | Q31: 0 | S31: 0 | U31: 0 | W31: 0 | Y31: 0 | AA31: 0 | AC31: 0 | AE31: 0 | AG31: 0 | AI31: 0 | AK31: 0 | AM31: 0 | AN31: 18146.718 | AO31: 1 | AP31: PROBABILISTICO | AQ31: 0.0025062657 | AR31: 45.480496 | AS31: ASMA | AT31: 18
A32: CPI_86 | B32: DEPORTOLOGIA PRIMERA VEZ/PROGRAMAS (solo si se requiere) | C32: Consultas | D32: 1 | E32: 60236.093 | G32: 0 | I32: 0 | K32: 0 | M32: 0 | O32: 0 | Q32: 0 | S32: 0 | U32: 0 | W32: 0 | Y32: 0 | AA32: 0 | AC32: 0 | AE32: 0 | AG32: 0 | AI32: 0 | AK32: 0 | AM32: 0 | AN32: 60236.093 | AO32: 1 | AP32: PROBABILISTICO | AQ32: 0.025062657 | AR32: 1509.6765 | AS32: ASMA | AT32: 18
A33: CPI_87 | B33: DEPORTOLOGIA CONTROL/PROGRAMAS (solo si se requiere) | C33: Consultas | E33: 0 | G33: 0 | I33: 0 | K33: 0 | M33: 0 | O33: 0 | P33: 1 | Q33: 62748.232 | S33: 0 | U33: 0 | W33: 0 | Y33: 0 | AA33: 0 | AC33: 0 | AE33: 0 | AG33: 0 | AI33: 0 | AK33: 0 | AM33: 0 | AN33: 62748.232 | AO33: 1 | AP33: PROBABILISTICO | AQ33: 0.0083542189 | AR33: 524.21247 | AS33: ASMA | AT33: 18
A34: CPI_88 | B34: DEPORTOLOGIA EGRESO/PROGRAMAS (solo si se requiere) | C34: Consultas | E34: 0 | G34: 0 | I34: 0 | K34: 0 | M34: 0 | O34: 0 | Q34: 0 | S34: 0 | U34: 0 | W34: 0 | Y34: 0 | AA34: 0 | AC34: 0 | AE34: 0 | AG34: 0 | AI34: 0 | AK34: 0 | AL34: 1 | AM34: 62748.232 | AN34: 62748.232 | AO34: 1 | AP34: PROBABILISTICO | AQ34: 0 | AR34: 0 | AS34: ASMA | AT34: 18
A35: CPI_31 | B35: REHABILITACIoN EGRESO / PROGRAMAS | C35: Terapias | E35: 0 | G35: 0 | I35: 0 | K35: 0 | M35: 0 | O35: 0 | Q35: 0 | S35: 0 | U35: 0 | W35: 0 | Y35: 0 | AA35: 0 | AC35: 0 | AE35: 0 | AG35: 0 | AI35: 0 | AK35: 0 | AL35: 1 | AM35: 31881.452 | AN35: 31881.452 | AO35: 1 | AP35: FIJO | AQ35: 1 | AR35: 31881.452 | AS35: ASMA | AT35: 18
A36: CPI_02 | B36: REHABILITACION INGRESO / PROGRAMAS | C36: Terapias | E36: 0 | G36: 0 | H36: 1 | I36: 31881.452 | K36: 0 | M36: 0 | O36: 0 | Q36: 0 | S36: 0 | U36: 0 | W36: 0 | Y36: 0 | AA36: 0 | AC36: 0 | AE36: 0 | AG36: 0 | AI36: 0 | AK36: 0 | AM36: 0 | AN36: 31881.452 | AO36: 1 | AP36: FIJO | AQ36: 1 | AR36: 31881.452 | AS36: ASMA | AT36: 18
A37: CPI_79 | B37: CONSULTA CONTROL MEDICINA GENERAL / PROGRAMAS (Todas las que requiera el paciente) | C37: Consultas | E37: 0 | G37: 0 | I37: 0 | K37: 0 | M37: 0 | O37: 0 | Q37: 0 | S37: 0 | U37: 0 | W37: 0 | Y37: 0 | AA37: 0 | AC37: 0 | AE37: 0 | AG37: 0 | AI37: 0 | AK37: 0 | AM37: 0 | AN37: 0 | AO37: 0 | AP37: PROBABILISTICO | AQ37: 0 | AR37: 0 | AS37: ASMA | AT37: 18
A38: CPI_23 | B38: PRUEBA DE BRONCOPROVOCACIÓN ESPECÍFICA (ALERGENO) O INESPECÍFICA | C38: Diagnosticos | D38: 1 | E38: 232601.87 | G38: 0 | I38: 0 | K38: 0 | M38: 0 | O38: 0 | Q38: 0 | S38: 0 | U38: 0 | W38: 0 | Y38: 0 | AA38: 0 | AC38: 0 | AE38: 0 | AG38: 0 | AI38: 0 | AK38: 0 | AM38: 0 | AN38: 232601.87 | AO38: 1 | AP38: PROBABILISTICO | AQ38: 0.015037594 | AR38: 3497.7725 | AS38: ASMA | AT38: 18
A39: CPI_19 | B39: CONSULTA PRIMERA VEZ ALERGOLOGIA / PROGRAMAS | C39: Consultas | D39: 1 | E39: 85060.599 | G39: 0 | I39: 0 | K39: 0 | M39: 0 | O39: 0 | Q39: 0 | S39: 0 | U39: 0 | W39: 0 | Y39: 0 | AA39: 0 | AC39: 0 | AE39: 0 | AG39: 0 | AI39: 0 | AK39: 0 | AM39: 0 | AN39: 85060.599 | AO39: 1 | AP39: FIJO | AQ39: 1 | AR39: 85060.599 | AS39: ASMA | AT39: 18
A40: CPI_72 | B40: CONSULTA ESPECIALIZADA PRIMERA VEZ REHABILITACIoN/PROGRAMAS | C40: Consultas | D40: 1 | E40: 26897.08 | G40: 0 | I40: 0 | K40: 0 | M40: 0 | O40: 0 | Q40: 0 | S40: 0 | U40: 0 | W40: 0 | Y40: 0 | AA40: 0 | AC40: 0 | AE40: 0 | AG40: 0 | AI40: 0 | AK40: 0 | AM40: 0 | AN40: 26897.08 | AO40: 1 | AP40: PROBABILISTICO | AQ40: 0 | AR40: 0 | AS40: ASMA | AT40: 18
...

Sheet Categorias
A1: CODIGO | B1: SERVICIO | C1: VALOR
A2: 890305 | B2: ENFERMERIA PRIMERA VEZ/PROGRAMAS | C2: Consultas
A3: CPI_01 | B3: INGRESO PROGRAMAS INTEGRALES | C3: Gestion y seguimiento
A4: CPI_02 | B4: REHABILITACION INGRESO / PROGRAMAS | C4: Terapias
A5: CPI_03 | B5: REHABILITACION CONTROL / PROGRAMAS (1, 2 o 3 Sesiones semana) | C5: Terapias
A6: CPI_04 | B6: CONSULTA PRIMERA VEZ MEDICINA INTERNA / PROGRAMAS | C6: Consultas
A7: CPI_05 | B7: CONSULTA CONTROL MEDICINA INTERNA / PROGRAMAS (Segun indicacion medica) | C7: Consultas
A8: CPI_06 | B8: CONSULTA PRIORITARIA/ PROGRAMAS (Todas las que requiera el paciente) | C8: Consultas
A9: CPI_08 | B9: EGRESO PROGRAMAS INTEGRALES | C9: Gestion y seguimiento
A10: CPI_09 | B10: ACTIVIDAD EDUCATIVA / PROGRAMAS | C10: Educacion
A11: CPI_10 | B11: CONTACTO DE SEGUIMIENTO Y/O TELEFONICO / PROGRAMAS | C11: Gestion y seguimiento
A12: CPI_11 | B12: CONSULTA PRIMERA VEZ NEUMOLOGIA ADULTO / PROGRAMAS | C12: Consultas
A13: CPI_12 | B13: CONSULTA CONTROL NEUMOLOGIA ADULTO / PROGRAMAS (Segun indicacion medica) | C13: Consultas
A14: CPI_13 | B14: CONSULTA PRIMERA VEZ NEUMOLOGIA PEDIATRICA / PROGRAMAS | C14: Consultas
... A51: INO007 | B51: INGRESO CESACIoN TABAQUICA | C51: Gestion y seguimiento

Sheet ASMA costo
A1: PROGRAMA REHABILITACIoN PULMONAR/ASMA (12 MESES)
A2: Servicios del Programa: | B2: Programa Rehabilitacion Pulmonar / Asma | C2: CATEGORIA | D2: MES 1 | E2: COSTO | F2: MES 2 | G2: COSTO2 | H2: MES 3 | I2: COSTO3 | J2: MES 4 | K2: COSTO4 | L2: MES 5 | M2: COSTO5 | N2: MES 6 | O2: COSTO6 | P2: MES 7 | Q2: COSTO7 | R2: MES 8 | S2: COSTO8 | T2: MES 9 | U2: COSTO9 | V2: MES 10 | W2: COSTO10 | X2: MES 11 | Y2: COSTO11 | Z2: MES 12 | AA2: COSTO12 | AB2: TOTAL | AC2: TOTAL SERVICIOS | AD2: Modalidad | AE2: % de las personas que lo usaron | AF2: VALOR COSTO | AG2: RUTA | AH2: DURACION
A3: CPI_01 | B3: INGRESO PROGRAMAS INTEGRALES | C3: =_xlfn.XLOOKUP(Tabla428[[#This Row],[Servicios del Programa:]],Tabla151[CODIGO],Tabla151[VALOR]) -> Gestion y seguimiento | D3: 1 | E3: {=IF(D3="X",(_xlfn.XLOOKUP($B3,Tabla1[SERVICIO],Tabla1[VALOR])*1),IF(D3>=1,_xlfn.XLOOKUP($B3,Tabla1[SERVICIO],Tabla1[VALOR]*D3),0))} -> 20552.756 | G3: {=IF(F3="X",(_xlfn.XLOOKUP($B3,Tabla1[SERVICIO],Tabla1[VALOR])*1),IF(F3>=1,_xlfn.XLOOKUP($B3,Tabla1[SERVICIO],Tabla1[VALOR]*F3),0))} -> 0 | I3: {=IF(H3="X",(_xlfn.XLOOKUP($B3,Tabla1[SERVICIO],Tabla1[VALOR])*1),IF(H3>=1,_xlfn.XLOOKUP($B3,Tabla1[SERVICIO],Tabla1[VALOR]*H3),0))} -> 0 | K3: {=IF(J3="X",(_xlfn.XLOOKUP($B3,Tabla1[SERVICIO],Tabla1[VALOR])*1),IF(J3>=1,_xlfn.XLOOKUP($B3,Tabla1[SERVICIO],Tabla1[VALOR]*J3),0))} -> 0 | M3: {=IF(L3="X",(_xlfn.XLOOKUP($B3,Tabla1[SERVICIO],Tabla1[VALOR])*1),IF(L3>=1,_xlfn.XLOOKUP($B3,Tabla1[SERVICIO],Tabla1[VALOR]*L3),0))} -> 0 | O3: {=IF(N3="X",(_xlfn.XLOOKUP($B3,Tabla1[SERVICIO],Tabla1[VALOR])*1),IF(N3>=1,_xlfn.XLOOKUP($B3,Tabla1[SERVICIO],Tabla1[VALOR]*N3),0))} -> 0 | Q3: {=IF(P3="X",(_xlfn.XLOOKUP($B3,Tabla1[SERVICIO],Tabla1[VALOR])*1),IF(P3>=1,_xlfn.XLOOKUP($B3,Tabla1[SERVICIO],Tabla1[VALOR]*P3),0))} -> 0 | S3: {=IF(R3="X",(_xlfn.XLOOKUP($B3,Tabla1[SERVICIO],Tabla1[VALOR])*1),IF(R3>=1,_xlfn.XLOOKUP($B3,Tabla1[SERVICIO],Tabla1[VALOR]*R3),0))} -> 0 | U3: {=IF(T3="X",(_xlfn.XLOOKUP($B3,Tabla1[SERVICIO],Tabla1[VALOR])*1),IF(T3>=1,_xlfn.XLOOKUP($B3,Tabla1[SERVICIO],Tabla1[VALOR]*T3),0))} -> 0 | W3: {=IF(V3="X",(_xlfn.XLOOKUP($B3,Tabla1[SERVICIO],Tabla1[VALOR])*1),IF(V3>=1,_xlfn.XLOOKUP($B3,Tabla1[SERVICIO],Tabla1[VALOR]*V3),0))} -> 0 | Y3: {=IF(X3="X",(_xlfn.XLOOKUP($B3,Tabla1[SERVICIO],Tabla1[VALOR])*1),IF(X3>=1,_xlfn.XLOOKUP($B3,Tabla1[SERVICIO],Tabla1[VALOR]*X3),0))} -> 0 | AA3: {=IF(Z3="X",(_xlfn.XLOOKUP($B3,Tabla1[SERVICIO],Tabla1[VALOR])*1),IF(Z3>=1,_xlfn.XLOOKUP($B3,Tabla1[SERVICIO],Tabla1[VALOR]*Z3),0))} -> 0 | AB3: =SUM(E3,G3,I3,K3+M3,O3,Q3,S3,U3,W3,Y3,AA3) -> 20552.756 | AC3: =+Tabla428[[#This Row],[MES 1]]+Tabla428[[#This Row],[MES 2]]+Tabla428[[#This Row],[MES 3]]+Tabla428[[#This Row],[MES 4]]+Tabla428[[#This Row],[MES 5]]+Tabla428[[#This Row],[MES 6]]+Tabla428[[#This Row],[MES 7]]+Tabla428[[#This Row],[MES 8]]+Tabla428[[#This Row],[MES 9]]+Tabla428[[#This Row],[MES 10]]+Tabla428[[#This Row],[MES 11]]+Tabla428[[#This Row],[MES 12]] -> 1 | AD3: FIJO | AE3: 1 | AF3: =+Tabla428[[#This Row],[TOTAL]]*AE3 -> 20552.756 | AG3: ASMA | AH3: 12
A4: CPI_83 | B4: TRABAJO SOCIAL PRIMERA VEZ/PROGRAMAS | C4: =_xlfn.XLOOKUP(Tabla428[[#This Row],[Servicios del Programa:]],Tabla151[CODIGO],Tabla151[VALOR]) -> Consultas | D4: 1 | E4: {=IF(D4="X",(_xlfn.XLOOKUP($B4,Tabla1[SERVICIO],Tabla1[VALOR])*1),IF(D4>=1,_xlfn.XLOOKUP($B4,Tabla1[SERVICIO],Tabla1[VALOR]*D4),0))} -> 17887.389 | G4: {=IF(F4="X",(_xlfn.XLOOKUP($B4,Tabla1[SERVICIO],Tabla1[VALOR])*1),IF(F4>=1,_xlfn.XLOOKUP($B4,Tabla1[SERVICIO],Tabla1[VALOR]*F4),0))} -> 0 | I4: {=IF(H4="X",(_xlfn.XLOOKUP($B4,Tabla1[SERVICIO],Tabla1[VALOR])*1),IF(H4>=1,_xlfn.XLOOKUP($B4,Tabla1[SERVICIO],Tabla1[VALOR]*H4),0))} -> 0 | K4: {=IF(J4="X",(_xlfn.XLOOKUP($B4,Tabla1[SERVICIO],Tabla1[VALOR])*1),IF(J4>=1,_xlfn.XLOOKUP($B4,Tabla1[SERVICIO],Tabla1[VALOR]*J4),0))} -> 0 | M4: {=IF(L4="X",(_xlfn.XLOOKUP($B4,Tabla1[SERVICIO],Tabla1[VALOR])*1),IF(L4>=1,_xlfn.XLOOKUP($B4,Tabla1[SERVICIO],Tabla1[VALOR]*L4),0))} -> 0 | O4: {=IF(N4="X",(_xlfn.XLOOKUP($B4,Tabla1[SERVICIO],Tabla1[VALOR])*1),IF(N4>=1,_xlfn.XLOOKUP($B4,Tabla1[SERVICIO],Tabla1[VALOR]*N4),0))} -> 0 | Q4: {=IF(P4="X",(_xlfn.XLOOKUP($B4,Tabla1[SERVICIO],Tabla1[VALOR])*1),IF(P4>=1,_xlfn.XLOOKUP($B4,Tabla1[SERVICIO],Tabla1[VALOR]*P4),0))} -> 0 | S4: {=IF(R4="X",(_xlfn.XLOOKUP($B4,Tabla1[SERVICIO],Tabla1[VALOR])*1),IF(R4>=1,_xlfn.XLOOKUP($B4,Tabla1[SERVICIO],Tabla1[VALOR]*R4),0))} -> 0 | U4: {=IF(T4="X",(_xlfn.XLOOKUP($B4,Tabla1[SERVICIO],Tabla1[VALOR])*1),IF(T4>=1,_xlfn.XLOOKUP($B4,Tabla1[SERVICIO],Tabla1[VALOR]*T4),0))} -> 0 | W4: {=IF(V4="X",(_xlfn.XLOOKUP($B4,Tabla1[SERVICIO],Tabla1[VALOR])*1),IF(V4>=1,_xlfn.XLOOKUP($B4,Tabla1[SERVICIO],Tabla1[VALOR]*V4),0))} -> 0 | Y4: {=IF(X4="X",(_xlfn.XLOOKUP($B4,Tabla1[SERVICIO],Tabla1[VALOR])*1),IF(X4>=1,_xlfn.XLOOKUP($B4,Tabla1[SERVICIO],Tabla1[VALOR]*X4),0))} -> 0 | AA4: {=IF(Z4="X",(_xlfn.XLOOKUP($B4,Tabla1[SERVICIO],Tabla1[VALOR])*1),IF(Z4>=1,_xlfn.XLOOKUP($B4,Tabla1[SERVICIO],Tabla1[VALOR]*Z4),0))} -> 0 | AB4: =+E4+G4+I4+K4+M4+O4+Q4+S4+U4+W4+Y4+AA4 -> 17887.389 | AC4: =+Tabla428[[#This Row],[MES 1]]+Tabla428[[#This Row],[MES 2]]+Tabla428[[#This Row],[MES 3]]+Tabla428[[#This Row],[MES 4]]+Tabla428[[#This Row],[MES 5]]+Tabla428[[#This Row],[MES 6]]+Tabla428[[#This Row],[MES 7]]+Tabla428[[#This Row],[MES 8]]+Tabla428[[#This Row],[MES 9]]+Tabla428[[#This Row],[MES 10]]+Tabla428[[#This Row],[MES 11]]+Tabla428[[#This Row],[MES 12]] -> 1 | AD4: FIJO | AE4: 1 | AF4: =+Tabla428[[#This Row],[TOTAL]]*AE4 -> 17887.389 | AG4: ASMA | AH4: 12
